<!DOCTYPE html>
<html lang="en">

<head>
    <meta charset="UTF-8">
    <meta name="viewport" content="width=device-width, initial-scale=1.0">
    <meta http-equiv="X-UA-Compatible" content="ie=edge">
    <title>Document</title>
    <script src="https://cdn.bootcss.com/jquery/3.4.1/jquery.min.js"></script>
</head>

<body>

    <script>
        // JS是单线程的，同步是几件事一个事做完再做下个事，异步是几件事中间一件事可先跳过，剩下的事全部执行完后执行跳过的事。异步比如：定时器、事件绑定、Ajax读取数据、回调函数。
        // 异步
        setTimeout(function () {
            console.log(3);
        }, 5000)
        console.log(1);
        console.log(2);

        // 解决异步编程，异步操作以同步的方式去执行
        // 需求：存钱，先存一百再取一百
        // 1）回调函数
        var money = 100;

        function test1(callback) { //(主函数)
            console.log('执行了test1');  //主函数任务代码
            money = money + 100;
            setTimeout(function () {
                callback();
            }, 1000);
        }
        function test2() {//回调函数
            console.log('执行了test2');
            money = money - 100;
        }

        test1(test2); // 执行
        //#region
        //#endregion
        //2)Promise
        // Promise 的含义
        // 基本用法
        // Promise.prototype.then()
        // Promise.prototype.catch()
        // Promise.prototype.finally()
        // Promise.all()
        // Promise.race()
        // Promise.allSettled()
        // Promise.any()
        // Promise.resolve()
        // Promise.reject()
        // 应用
        // Promise.try()


        // 不用then
        // function a() {
        //     let mgs = true;
        //     return new Promise((resolve, reject) => {
        //         setTimeout(() => {
        //             if (mgs == true) {
        //                 console.log('执行a函数内容')
        //                 resolve('res')
        //             } else {
        //                 reject('执行错误')
        //             }
        //         }, 1000);
        //     })
        // }
        // function b() {
        //     console.log('执行b函数内容')
        // }
        // a();
        // b();

        // 用then
        function a() {
            let mgs = true;
            return new Promise((resolve, reject) => {
                setTimeout(() => {
                    if (mgs == true) {
                        console.log('执行a函数内容')
                        resolve('res')
                    } else {
                        reject('热行错误')
                    }
                }, 1000);
            })
        }
        function b() {
            console.log('执行b函数内容')
        }
        a().then(res => {
            console.log(res)
            b();
        });
        // 3）async - await的基础用法
        // 3.1 async 函数和普通函数一样执行，是generator的语法糖。
        // 3.2 async函数的返回值是Promise 对象，所以可以用.then方法指定下一步的操作，return语句返回的值，会成为then方法回调函数的参数

        async function test() {
            return 'hello world'
        }
        test().then(result => {
            console.log(result);
        })


        function test1() {
            //返回一个promise-并且调用resolve之后await才会执行成功
            return new Promise((resolve, reject) => {
                //模拟异步操作请求
                setTimeout(() => {
                    console.log("打印test1");
                    resolve();
                    1000
                });
            });
        }
        function test2() {
            //返回一个promise-并且调用resolve之后await才会执行成功
            return new Promise((resolve, reject) => {
                //模拟异步操作请求
                setTimeout(() => {
                    console.log("打印test2");
                    resolve();
                },
                    1000);
            });
        }

        async function asyncPrint() {
            try {
                console.log("asyncPrint执行前");
                console.time('asyncPrint执行时间');
                await this.test1();//一旦遇到reject()或者设有执行resolve则会中断执行
                await this.test2(); //一旦遇到reject()或者设有执行resolve则会中断执行
                console.timeEnd('asyncPrint执行时间')
                console.log("asyncPrint执行后");
            } catch (err) {
                console.log(err);
            }
        };
        asyncPrint();

        // await后面的函数建议 返回 Promise对象(即return new Promise((resolve, reject) => { })) 并且主动调用resolve()才能够进行后续的then或者是后续的await操作，倘若是执行了reject(reject的参数会被catch方法的回调函数接收到)或者throw抛出错误之类的就会导致当前执行中断。
        // 注意1：await命令后面的Promise对象，运行结果可能是rejected，所以最好把await命令放在try…catch代码块中。
        // 注意2：多个await命令后面的异步操作，如果不存在先后关联，最好让它们同时触发。不然会增加耗时；
        // 这样做的好处就是，如果两个await直接运行则需要2秒的时间才会运行后续的内容，但是像这样处理一下，两个就会同时开始，即只需要1秒就可以运行后续的内容了。
        async function asyncPrintSimultaneously() {
            try {
                console.log("asyncPrintSimultaneously执行前");
                console.time('asyncPrintSimultaneously执行时间');
                let t1 = this.test1();//一旦遇到reject()或者设有执行resolve则会中断执行
                let t2 = this.test2();//一旦遇到reject()或者设有执行resolve则会中断执行
                await t1;
                await t2;
                console.timeEnd('asyncPrintSimultaneously执行时间')
                console.log("asyncPrintSimultaneously执行后");
            } catch (err) {
                console.log(err);
            }
        };
        asyncPrintSimultaneously();

        //p1是一个 Promise，3 秒之后变为rejected。p2的状态在 1 秒之后改变，resolve方法返回的是p1。由于p2返回的是另一个 Promise，导致p2自己的状态无效了，由p1的状态决定p2的状态。所以，后面的then语句都变成针对后者（p1）。又过了 2 秒，p1变为rejected，导致触发catch方法指定的回调函数。
        const p1 = new Promise(function (resolve, reject) {
            setTimeout(() => reject(new Error('fail')), 3000)
        })

        const p2 = new Promise(function (resolve, reject) {
            setTimeout(() => resolve(p1), 1000)
        })

        p2
            .then(result => console.log(result))
            .catch(error => console.log(error))
        // Error: fail

        // 调用resolve或reject并不会终结 Promise 的参数函数的执行，立即 resolved 的 Promise 是在本轮事件循环的末尾执行，总是晚于本轮循环的同步任务，最好在它们前面加上return语句，这样就不会有意外。
        new Promise((resolve, reject) => {
            resolve(1);
            console.log(2);
        }).then(r => {
            console.log(r);
        });
        // 2
        // 1
        new Promise((resolve, reject) => {
            return resolve(1);
            // 后面的语句不会执行
            console.log(2);
        })
        const promise = new Promise(function (resolve, reject) {
            resolve('ok');
            throw new Error('test');
        });
        // 如果异步操作抛出错误，状态就会变为rejected，就会调用catch()方法指定的回调函数，处理这个错误。另外，then()方法指定的回调函数，如果运行中抛出错误，也会被catch()方法捕获。
        // Promise 在resolve语句后面，再抛出错误，不会被捕获，等于没有抛出。因为 Promise 的状态一旦改变，就永久保持该状态，不会再变了。
        // Promise 对象的错误具有“冒泡”性质，会一直向后传递，直到被捕获为止。也就是说，错误总是会被下一个catch语句捕获。
        promise
            .then(function (value) { console.log(value) })
            .catch(function (error) { console.log(error) });
        // ok

        // Promise 内部的错误不会影响到 Promise 外部的代码，通俗的说法就是“Promise 会吃掉错误”
        const someAsyncThing = function () {
            return new Promise(function (resolve, reject) {
                // 下面一行会报错，因为x没有声明
                resolve(x + 2);
            });
        };

        someAsyncThing().then(function () {
            console.log('everything is great');
        });

        setTimeout(() => { console.log(123) }, 2000);
        // Uncaught (in promise) ReferenceError: x is not defined
        // 123
        // Promise.prototype.finally()
        // 如果不使用finally方法，同样的语句需要为成功和失败两种情况各写一次。有了finally方法，则只需要写一次。
        promise
            .finally(() => {
                // 语句
            });

        // 等同于
        promise
            .then(
                result => {
                    // 语句
                    return result;
                },
                error => {
                    // 语句
                    throw error;
                }
            );
        Promise.prototype.finally = function (callback) {
            let P = this.constructor;
            return this.then(
                value => P.resolve(callback()).then(() => value),
                reason => P.resolve(callback()).then(() => { throw reason })
            );
        };
        // Promise.all()
        // Promise.all()方法用于将多个 Promise 实例，包装成一个新的 Promise 实例。
        // Promise.all()方法接受一个数组作为参数，p1、p2、p3都是 Promise 实例，如果不是，就会先调用下面讲到的Promise.resolve方法，将参数转为 Promise 实例，再进一步处理。另外，Promise.all()方法的参数可以不是数组，但必须具有 Iterator 接口，且返回的每个成员都是 Promise 实例。
        // p的状态由p1、p2、p3决定，分成两种情况。
        // （1）只有p1、p2、p3的状态都变成fulfilled，p的状态才会变成fulfilled，此时p1、p2、p3的返回值组成一个数组，传递给p的回调函数。
        // （2）只要p1、p2、p3之中有一个被rejected，p的状态就变成rejected，此时第一个被reject的实例的返回值，会传递给p的回调函数。
        const p = Promise.all([p1, p2, p3]);

        // promises是包含 6 个 Promise 实例的数组，只有这 6 个实例的状态都变成fulfilled，或者其中有一个变为rejected，才会调用Promise.all方法后面的回调函数。
        // 生成一个Promise对象的数组
        const promises = [2, 3, 5, 7, 11, 13].map(function (id) {
            return getJSON('/post/' + id + ".json");
        });
        Promise.all(promises).then(function (posts) {
            // ...
        }).catch(function (reason) {
            // ...
        });
        // 如果作为参数的 Promise 实例，自己定义了catch方法，那么它一旦被rejected，并不会触发Promise.all()的catch方法。
        const p11 = new Promise((resolve, reject) => {
            resolve('hello');
        })
            .then(result => result)
            .catch(e => e);

        const p22 = new Promise((resolve, reject) => {
            throw new Error('报错了');
        })
            .then(result => result)
            .catch(e => e);

        Promise.all([p11, p22])
            .then(result => console.log(result))
            .catch(e => console.log(e));
        // ["hello", Error: 报错了]


        // Promise.race()
        // Promise.race()方法同样是将多个 Promise 实例，包装成一个新的 Promise 实例。

        const race = Promise.race([p1, p2, p3]);
        // 上面代码中，只要p1、p2、p3之中有一个实例率先改变状态，p的状态就跟着改变。那个率先改变的 Promise 实例的返回值，就传递给p的回调函数。

        // Promise.race()方法的参数与Promise.all()方法一样，如果不是 Promise 实例，就会先调用下面讲到的Promise.resolve()方法，将参数转为 Promise 实例，再进一步处理。
        // 如果 5 秒之内fetch方法无法返回结果，变量p的状态就会变为rejected，从而触发catch方法指定的回调函数
        const pp = Promise.race([
            fetch('/resource-that-may-take-a-while'),
            new Promise(function (resolve, reject) {
                setTimeout(() => reject(new Error('request timeout')), 5000)
            })
        ]);

        pp
            .then(console.log)
            .catch(console.error);


        // Promise.allSettled()方法接受一个数组作为参数，数组的每个成员都是一个 Promise 对象，并返回一个新的 Promise 对象。只有等到参数数组的所有 Promise 对象都发生状态变更（不管是fulfilled还是rejected），返回的 Promise 对象才会发生状态变更。
        const resolved = Promise.resolve(42);
        const rejected = Promise.reject(-1);
        const allSettledPromise = Promise.allSettled([resolved, rejected]);

        allSettledPromise.then(function (results) {
            console.log(results);
        });
        // [
        //    { status: 'fulfilled', value: 42 },
        //    { status: 'rejected', reason: -1 }
        // ]
        // Promise.allSettled()的返回值allSettledPromise，状态只可能变成fulfilled。它的回调函数接收到的参数是数组results。该数组的每个成员都是一个对象，对应传入Promise.allSettled()的数组里面的两个 Promise 对象。
        // results的每个成员是一个对象，对象的格式是固定的，对应异步操作的结果。
        // // 异步操作成功时
        // { status: 'fulfilled', value: value }
        // // 异步操作失败时
        // { status: 'rejected', reason: reason }


        // Promise.any()
        // 只要参数实例有一个变成fulfilled状态，包装实例就会变成fulfilled状态；如果所有参数实例都变成rejected状态，包装实例就会变成rejected状态。
        // Promise.any()跟Promise.race()方法很像，只有一点不同，就是Promise.any()不会因为某个 Promise 变成rejected状态而结束，必须等到所有参数 Promise 变成rejected状态才会结束。


        // Promise.resolve() 将现有对象转为 Promise 对象
        const jsPromise = Promise.resolve($.ajax('/whatever.json'));
        Promise.resolve('foo')
        // 等价于
        new Promise(resolve => resolve('foo'))
        // （1）参数是一个 Promise 实例, 不做任何修改、原封不动地返回
        // （2）参数是一个thenable对象,Promise.resolve()方法会将这个对象转为 Promise 对象，然后就立即执行thenable对象的then()方法。
        let thenable = {
            then: function (resolve, reject) {
                resolve(42);
            }
        };

        let resolveA = Promise.resolve(thenable);
        resolveA.then(function (value) {
            console.log(value);  // 42
        });
        // （3）参数不是具有then()方法的对象，或根本就不是对象,Promise.resolve()方法返回一个新的 Promise 对象，状态为resolved。
        const ppp = Promise.resolve('Hello');
        ppp.then(function (s) {
            console.log(s)
        });
        // Hello
        // （4）不带有任何参数
        const pppp = Promise.resolve();
        pppp.then(function () {
            // ...
        });
        // 需要注意的是，立即resolve()的 Promise 对象，是在本轮“事件循环”（event loop）的结束时执行，而不是在下一轮“事件循环”的开始时。
        setTimeout(function () {
            console.log('three');
        }, 0);
        Promise.resolve().then(function () {
            console.log('two');
        });
        console.log('one');
        // one
        // two
        // three
        // 上面代码中，setTimeout(fn, 0)在下一轮“事件循环”开始时执行，Promise.resolve()在本轮“事件循环”结束时执行，console.log('one')则是立即执行，因此最先输出。


        // Promise.reject(reason)方法也会返回一个新的 Promise 实例，该实例的状态为rejected。
        const preject = Promise.reject('出错了');
        // 等同于
        const preject1 = new Promise((resolve, reject) => reject('出错了'))

        p.then(null, function (s) {
            console.log(s)
        });
        // 出错了
        // 上面代码生成一个 Promise 对象的实例p，状态为rejected，回调函数会立即执行。
        // Promise.reject()方法的参数，会原封不动地作为reject的理由，变成后续方法的参数。
        Promise.reject('出错了')
            .catch(e => {
                console.log(e === '出错了')
            })
        // true
        // 上面代码中，Promise.reject()方法的参数是一个字符串，后面catch()方法的参数e就是这个字符串。


        // Generator 函数与 Promise 的结合
        // 使用 Generator 函数管理流程，遇到异步操作的时候，通常返回一个Promise对象。

        function getFoo() {
            return new Promise(function (resolve, reject) {
                resolve('foo');
            });
        }

        const g = function* () {
            try {
                const foo = yield getFoo();
                console.log(foo);
            } catch (e) {
                console.log(e);
            }
        };

        function run(generator) {
            const it = generator();

            function go(result) {
                if (result.done) return result.value;

                return result.value.then(function (value) {
                    return go(it.next(value));
                }, function (error) {
                    return go(it.throw(error));
                });
            }

            go(it.next());
        }

        run(g);
        // 上面代码的 Generator 函数g之中，有一个异步操作getFoo，它返回的就是一个Promise对象。函数run用来处理这个Promise对象，并调用下一个next方法。


        // Promise.try()
        // 实际开发中，经常遇到一种情况：不知道或者不想区分，函数f是同步函数还是异步操作，但是想用 Promise 来处理它。因为这样就可以不管f是否包含异步操作，都用then方法指定下一步流程，用catch方法处理f抛出的错误。一般就会采用下面的写法。

        Promise.resolve().then(f)
        // 上面的写法有一个缺点，就是如果f是同步函数，那么它会在本轮事件循环的末尾执行。

        const f = () => console.log('now');
        Promise.resolve().then(f);
        console.log('next');
        // next
        // now
        // 上面代码中，函数f是同步的，但是用 Promise 包装了以后，就变成异步执行了。

        // 那么有没有一种方法，让同步函数同步执行，异步函数异步执行，并且让它们具有统一的 API 呢？回答是可以的，并且还有两种写法。第一种写法是用async函数来写。

        const f1 = () => console.log('now');
        (async () => f1())();
        console.log('next');
        // now
        // next
        // 上面代码中，第二行是一个立即执行的匿名函数，会立即执行里面的async函数，因此如果f是同步的，就会得到同步的结果；如果f是异步的，就可以用then指定下一步，就像下面的写法。

        // (async () => f())()
        //     .then(...)
        // 需要注意的是，async () => f()会吃掉f()抛出的错误。所以，如果想捕获错误，要使用promise.catch方法。

        // (async () => f())()
        // .then(...)
        // .catch(...)
        // 第二种写法是使用new Promise()。

        // const f = () => console.log('now');
        // (
        //     () => new Promise(
        //         resolve => resolve(f())
        //     )
        // )();
        // console.log('next');
        // now
        // next
        // 上面代码也是使用立即执行的匿名函数，执行new Promise()。这种情况下，同步函数也是同步执行的。
        // 鉴于这是一个很常见的需求，所以现在有一个提案，提供Promise.try方法替代上面的写法。

        // const f = () => console.log('now');
        // Promise.try(f);
        // console.log('next');
        // now
        // next
        // 事实上，Promise.try存在已久，Promise 库Bluebird、Q和when，早就提供了这个方法。
        // 由于Promise.try为所有操作提供了统一的处理机制，所以如果想用then方法管理流程，最好都用Promise.try包装一下。这样有许多好处，其中一点就是可以更好地管理异常。

        // function getUsername(userId) {
        //     return database.users.get({ id: userId })
        //         .then(function (user) {
        //             return user.name;
        //         });
        // }
        // 上面代码中，database.users.get()返回一个 Promise 对象，如果抛出异步错误，可以用catch方法捕获，就像下面这样写。

        // database.users.get({ id: userId })
        //     .then(...)
        //     .catch(...)
        // 但是database.users.get()可能还会抛出同步错误（比如数据库连接错误，具体要看实现方法），这时你就不得不用try...catch去捕获。

        // try {
        //     database.users.get({ id: userId })
        //         .then(...)
        //         .catch(...)
        // } catch (e) {
        //     // ...
        // }
        // 上面这样的写法就很笨拙了，这时就可以统一用promise.catch()捕获所有同步和异步的错误。

        // Promise.try(() => database.users.get({ id: userId }))
        //     .then(...)
        //     .catch(...)
        // 事实上，Promise.try就是模拟try代码块，就像promise.catch模拟的是catch代码块。





        //1、查出当前用户信息
        //2、按照当前用户的id查出他的课程
        //3、按照当前课程id查出分数
        // $.ajax({
        //     url: "mock/user.json",
        //     success(data) {
        //         console.log("查询用户：", data);
        //         $.ajax({
        //             url: `mock/user_corse_${data.id}.json`,
        //             success(data) {
        //                 console.log("查询到课程：", data);
        //                 $.ajax({
        //                     url: `mock/corse_score_${data.id}.json`,
        //                     success(data) {
        //                         console.log("查询到分数：", data);
        //                     },
        //                     error(error) {
        //                         console.log("出现异常了：" + error);
        //                     }
        //                 });
        //             },
        //             error(error) {
        //                 console.log("出现异常了：" + error);
        //             }
        //         });
        //     },
        //     error(error) {
        //         console.log("出现异常了：" + error);
        //     }
        // });


        //1、Promise可以封装异步操作
        // let p = new Promise((resolve, reject) => {
        //     //1、异步操作
        //     $.ajax({
        //         url: "mock/user.json",
        //         success: function (data) {
        //             console.log("查询用户成功:", data)
        //             resolve(data);
        //         },
        //         error: function (err) {
        //             reject(err);
        //         }
        //     });
        // });

        // p.then((obj) => {
        //     return new Promise((resolve, reject) => {
        //         $.ajax({
        //             url: `mock/user_corse_${obj.id}.json`,
        //             success: function (data) {
        //                 console.log("查询用户课程成功:", data)
        //                 resolve(data);
        //             },
        //             error: function (err) {
        //                 reject(err)
        //             }
        //         });
        //     })
        // }).then((data) => {
        //     console.log("上一步的结果", data)
        //     $.ajax({
        //         url: `mock/corse_score_${data.id}.json`,
        //         success: function (data) {
        //             console.log("查询课程得分成功:", data)
        //         },
        //         error: function (err) {
        //         }
        //     });
        // })

        // function get(url, data) {
        //     return new Promise((resolve, reject) => {
        //         $.ajax({
        //             url: url,
        //             data: data,
        //             success: function (data) {
        //                 resolve(data);
        //             },
        //             error: function (err) {
        //                 reject(err)
        //             }
        //         })
        //     });
        // }

        // get("mock/user.json")
        //     .then((data) => {
        //         console.log("用户查询成功~~~:", data)
        //         return get(`mock/user_corse_${data.id}.json`);
        //     })
        //     .then((data) => {
        //         console.log("课程查询成功~~~:", data)
        //         return get(`mock/corse_score_${data.id}.json`);
        //     })
        //     .then((data) => {
        //         console.log("课程成绩查询成功~~~:", data)
        //     })
        //     .catch((err) => {
        //         console.log("出现异常", err)
        //     });

    </script>
</body>

</html>